<?xml version="1.0" ?>
<robot name="libro">
   <material name="blue">
      <color rgba="0 0 0.8 1"/>
   </material>
   <material name="black">
      <color rgba="0 0 0 1"/>
   </material>
   <material name="red">
      <color rgba="0.8 0 0 1"/>
   </material>
   <link name="link0">
      <visual>
         <origin xyz="0 0 0.05" rpy="0 0 0"/>
         <geometry>
            <cylinder length="0.1" radius="0.1"/>
         </geometry>
         <material name="black"/>
      </visual>
   </link>
   <link name="link1">
      <visual>
         <origin xyz="0.0 0.0 0.1" rpy="0.0 0.0 0.0"/>
         <geometry>
            <box size="0.1 0.1 0.2"/>
         </geometry>
         <material name="blue"/>
      </visual>
   </link>
   <joint name="joint1" type="revolute">
      <parent link="link0"/>
      <child link="link1"/>
      <origin xyz="0 0 0" rpy="0 0 0"/>
      <axis xyz="0 0 1"/>
      <limit lower="-3.14" upper="3.14" effort="100.0" velocity="1.0"/>
   </joint>
   <link name="link2">
      <visual>
         <origin xyz="0.0 0.0 0.25" rpy="0.0 0.0 0.0"/>
         <geometry>
            <box size="0.1 0.1 0.5"/>
         </geometry>
         <material name="red"/>
      </visual>
   </link>
   <joint name="joint2" type="revolute">
      <parent link="link1"/>
      <child link="link2"/>
      <origin xyz="0 0 0.2" rpy="0 0 0"/>
      <axis xyz="1 0 0"/>
      <limit lower="-1.57" upper="1.57" effort="100.0" velocity="1.0"/>
   </joint>
   <link name="link3">
      <visual>
         <origin xyz="0.0 0.25 0.0" rpy="-1.5707963267948966 0.0 0.0"/>
         <geometry>
            <box size="0.1 0.1 0.5"/>
         </geometry>
         <material name="blue"/>
      </visual>
   </link>
   <joint name="joint3" type="revolute">
      <parent link="link2"/>
      <child link="link3"/>
      <origin xyz="0 0 0.5" rpy="0 0 0"/>
      <axis xyz="1 0 0"/>
      <limit lower="-1.57" upper="1.57" effort="100.0" velocity="1.0"/>
   </joint>
   <link name="link4">
      <visual>
         <origin xyz="0.0 0.25 0.0" rpy="-1.5707963267948966 0.0 0.0"/>
         <geometry>
            <cylinder length="0.5" radius="0.05"/>
         </geometry>
         <material name="red"/>
      </visual>
   </link>
   <joint name="joint4" type="prismatic">
      <parent link="link3"/>
      <child link="link4"/>
      <origin xyz="0 0.5 0" rpy="0 0 0"/>
      <axis xyz="0 1 0"/>
      <limit lower="-1.57" upper="1.57" effort="100.0" velocity="1.0"/>
   </joint>
   <link name="link5">
      <visual>
         <origin xyz="0.0 0.1 0.0" rpy="-1.5707963267948966 0.0 0.0"/>
         <geometry>
            <cylinder length="0.2" radius="0.05"/>
         </geometry>
         <material name="blue"/>
      </visual>
   </link>
   <joint name="joint5" type="prismatic">
      <parent link="link4"/>
      <child link="link5"/>
      <origin xyz="0 0.3 0" rpy="0 0 0"/>
      <axis xyz="0 1 0"/>
      <limit lower="0" upper="0.2" effort="100.0" velocity="1.0"/>
   </joint>
   <link name="link6">
      <visual>
         <origin xyz="0.0 0.25 0.0" rpy="-1.5707963267948966 0.0 0.0"/>
         <geometry>
            <box size="0.1 0.1 0.5"/>
         </geometry>
         <material name="red"/>
      </visual>
   </link>
   <joint name="joint6" type="revolute">
      <parent link="link5"/>
      <child link="link6"/>
      <origin xyz="0 0.2 0" rpy="0 0 0"/>
      <axis xyz="0 1 0"/>
      <limit lower="-1.57" upper="1.57" effort="100.0" velocity="1.0"/>
   </joint>
   <link name="link7">
      <visual>
         <origin xyz="0.0 0.1 0.0" rpy="-1.5707963267948966 0.0 0.0"/>
         <geometry>
            <box size="0.1 0.1 0.2"/>
         </geometry>
         <material name="blue"/>
      </visual>
   </link>
   <joint name="joint7" type="revolute">
      <parent link="link6"/>
      <child link="link7"/>
      <origin xyz="0 0.5 0" rpy="0 0 0"/>
      <axis xyz="0 1 0"/>
      <limit lower="-1.57" upper="1.57" effort="100.0" velocity="1.0"/>
   </joint>
</robot>
